Workbook

Sheet README
A1: K-State Baseball — Throwing Workload Model
B2: Turn distance, throw count, and velocity into one workload number — then use it to plan the next day/week.
B4: 1. What this workbook does
B6: Every throwing set a player does (a round of long toss, a bullpen, flat ground work) gets logged in the Throw Log tab with three inputs: distance, number of throws, and velocity. The model converts distance and velocity into two multipliers — a Distance Factor and an Intensity Factor — and multiplies them by the throw count to get a Set Workload number. Add up a player's daily workload, then track it against his own rolling history (7-day "acute" load vs. 28-day "chronic" load) on the Dashboard tab. The ratio of those two numbers — the Acute:Chronic Workload Ratio, or ACWR — tells you whether today's plan is a safe progression, should hold steady, or needs to back off. The Next Outing Planner tab turns that zone into a day-by-day throwing plan for the week ahead.
B12: 2. The workload formula
B14: Set Workload = Number of Throws × Distance Factor × Intensity Factor
B16: Distance Factor and Intensity Factor are multiplied as two SEPARATE numbers, not folded into one, because distance is not just a stand-in for velocity — they load the arm somewhat independently. Fleisig's own biomechanics lab compared mound pitching to long toss at several distances and found max-distance throws produced the HIGHEST elbow and shoulder torque of any condition tested — without any increase in ball velocity versus pitching (Fleisig, Bolt, Fortenbaugh, Wilk & Andrews, J Orthop Sports Phys Ther, 2011). Two throws released at the same measured mph are not equally stressful if one of them travels farther: covering extra distance without extra velocity means changing mechanics (more shoulder layback/external rotation, more trunk tilt, a higher looping arc), and it's that changed mechanics — not the number on a radar gun — that loads the joint. The study's authors called max-distance throws “the least efficient” (most torque for the least velocity gained) and recommended capping long toss around 180 ft thrown on a line for that reason. It's also why the interval-throwing-program researchers who built the ACWR model below (Reinold, Dowling, Fleisig, Macrina, Wilk, Streepy & Andrews, Int J Sports Phys Ther, 2024) modeled elbow torque on distance ALONE, not velocity — they found velocity doesn't correlate reliably with torque and varies too much pitcher to pitcher to be a consistent stress proxy, while distance does. (One smaller study found kinetics rising with distance but never exceeding pitching — so treat “does long toss ever exceed mound stress” as a genuinely open question, not settled science.)
B24: Intensity Factor scales with how many mph OFF the player's own Avg Top Velo (from the Roster tab) he threw — not a percentage of his single fastest pitch ever recorded. A one-time peak reading is noisy (adrenaline, a favorable radar angle, pure chance); the average of several of his hardest, most competitive readings is a more reliable “100% intent” line, and effort doesn't fall off in a straight percentage as velo drops — the last few mph near the top cost disproportionately more effort than the same few mph do lower down. A fixed mph-below-average gap tracks felt effort much better than a max-velo ratio does. One exception: for Bullpen and Game rows, Distance Factor is replaced by a flat Mound Factor, because the pitching distance never changes (60'6") and a mound delivery loads the arm well beyond what a flat-ground throw at that same short distance would — see the callout on the Reference tab. The exact band values throughout are a coaching model, not a lab-measured constant, and you should feel free to tune them for your staff's eye once you have a season of data to compare against.
B30: 3. Acute:Chronic Workload Ratio (ACWR)
B32: ACWR = (average daily workload over the trailing 7 days) ÷ (average daily workload over the trailing 28 days). It is the same framework Tim Gabbett popularized for injury-workload research (Br J Sports Med, 2016) and that the ASMI group (Reinold, Dowling, Fleisig, et al.) applied directly to pitchers' interval throwing programs, using 0.7–1.3 as the target range and flagging spikes above ~1.5 as high-risk in their workload-based throwing program study (IJSPT, 2024). This workbook uses: below 0.8 = room to progress, 0.8–1.3 = sweet spot, 1.3–1.5 = caution, above 1.5 = high risk. A quick honesty note: ACWR has real critics in the sports-science literature (Windt & Gabbett, 2019) — because the acute week is part of the chronic average, the ratio is mathematically coupled to itself, which can distort it at the extremes. Treat the ACWR zone as one signal among several — combine it with what the player is telling you about arm feel, not as a stand-alone verdict.
B38: 4. How to use this day to day
B40: 1) Add every player to the Roster tab with his Avg Top Velo (average of several of his hardest readings, not a single one-time peak — keep the peak too, it's just for reference). 2) After each throwing session, log it as ONE row in Throw Log — the main columns are his working-out segment (whatever distance he built out to, with its own throw count and velo). If he closes the session by working back in at 60' (very common), don't start a second row for it — use the dedicated 60' Throws / 60' Velo columns further right on that SAME row; they're added into that row's Set Workload automatically at the 60' Distance Factor. Game days work the same way but for pregame bullpen warm-up instead: the box-score pitch count leaves out pregame bullpen warm-up and every between-innings/entering warm-up pitch, so use the main columns for live pitches + in-game warm-up pitches, and the dedicated Warmup/Bullpen columns on that same row for whatever he threw getting loose in the pen beforehand. See the callouts on the Reference tab for worked examples of both patterns. 3) Open Dashboard, pick the player, and read his Zone and Guidance for today. 4) Open Next Outing Planner, pick the same player, tell it what he's building toward (a live Game or his next High Bullpen day) and that date — This Week's Plan below fills in automatically for every day between now and then, before a single throw is made, so you can adjust before, not after. 5) Re-check both tabs after each session — the Dashboard zone moves as new data comes in, and Next Outing Planner's plan for the days still ahead nudges itself up or down to match. Once he throws his outing/bullpen day, just update the date to his next one and the whole week regenerates.
B46: 5. Day Type Templates & Next Outing Planner
... B62: • Gabbett, T. "The training-injury prevention paradox." Br J Sports Med, 2016 — ACWR sweet spot (0.8–1.3) / danger zone (>1.5). • Reinold, M., Dowling, B., Fleisig, G., Macrina, L., Wilk, K., Streepy, J., Andrews, J. "An Interval Throwing Program for Baseball Pitchers Based upon Workload Data." Int J Sports Phys Ther, 2024 — 238,611 throws (111,196 long-toss) from 34 NCAA D-I pitchers; modeled elbow torque on DISTANCE, not velocity, because velocity didn't correlate reliably with torque pitcher to pitcher; direct precedent for applying 7-day/28-day ACWR to throwing distance/volume data. • Fleisig, G., Bolt, B., Fortenbaugh, D., Wilk, K., Andrews, J. "Biomechanical Comparison of Baseball Pitching and Long-Toss: Implications for Training and Rehabilitation." J Orthop Sports Phys Ther, 2011 — found max-distance long toss produces the highest elbow/shoulder torque of any condition tested, WITHOUT higher ball velocity than pitching; the basis for treating Distance Factor and Intensity Factor as separate, independent multipliers rather than one folded into the other. • Driveline Baseball, "Everything Long Toss and Long-Toss Programs" / "Pulldowns" — typical long-toss distance bands and pulldown intensity, used to set this workbook's Distance Factor anchor points. • MLB / USA Baseball Pitch Smart guidelines (mlb.com/pitch-smart) — precedent for tying required rest to recent throwing volume. • Windt, J. & Gabbett, T. "How do training and competition workloads relate to injury? The workload-injury aetiology model," and follow-up critiques — mathematical-coupling limitation of ACWR noted above. • NCAA Baseball Rules — Appendix F, Pitch/Between-Innings Clock Protocol (2025-26 rules cycle) — 5 warm-up pitches between innings for a continuing pitcher, 8 for a pitcher entering the game; basis for the Game-day throw-count guidance on the Reference tab. This model is a coaching decision-support tool built from these public frameworks, not a validated medical instrument. It does not replace your athletic trainer, your pitching coach's eye, or what a player tells you about his arm.

Sheet Reference
A1: Reference Tables — Workload Model Constants
A2: These drive every formula in Throw Log and Dashboard. Edit values here (not in formulas) to re-tune the model.
A4: Distance Factor Table — smooth: in-between distances fall on a straight line between these points
A5: Distance (ft) | B5: Distance Factor | C5: Description
A6: 60 | B6: 1 | C6: Warm-up / catch play — 60 ft and shorter all score 1.0
A7: 90 | B7: 1.3 | C7: Building distance (75 ft = 1.15, halfway between 60 and 90)
A8: 120 | B8: 1.7 | C8: Extension / stretch (105 ft = 1.5)
A9: 150 | B9: 2.2 | C9: Long toss (135 ft = 1.95)
A10: 180 | B10: 2.8 | C10: Max long toss (165 ft = 2.5)
A11: 210 | B11: 3.5 | C11: Pulldowns / max distance — 210 ft and beyond all score 3.5
A14: Intensity Factor Table (based on mph BELOW player's Avg Top Velo — not % of a single peak pitch)
A15: Effort doesn't fall off in a straight line as velo drops — near your top end, a couple mph off costs a lot more effort than the same couple mph do when you're playing catch. So this compares the throw's velo to the player's AVG top velo (Roster tab) as a flat mph gap, not a percentage of his single best-ever pitch. Uses the midpoint of the Velo Low–High range entered in Throw Log.
A16: Min Deficit (mph below Avg Top Velo) | B16: Intensity Factor | C16: Description
A17: 0 | B17: 2 | C17: Max effort — at or near Avg Top Velo (about 0–3 mph off)
A18: 4 | B18: 1.5 | C18: Compete / high intent (about 4–6 mph off)
A19: 7 | B19: 1 | C19: Building (about 7–9 mph off)
A20: 10 | B20: 0.6 | C20: Easy / recovery catch (10+ mph off)
A22: ACWR Zone Thresholds
A23: Min ACWR | B23: Zone | C23: Guidance
A24: 0 | B24: Undertrained | C24: Below 0.8 — there is room to progress distance/intensity next session.
A25: 0.8 | B25: Sweet Spot | C25: 0.8–1.3 — ideal loading zone; maintain the planned progression.
A26: 1.31 | B26: Caution | C26: 1.3–1.5 — hold volume/intensity flat; add a recovery day this week.
A27: 1.51 | B27: High Risk | C27: Above 1.5 — mandatory easy/rest day next session; cut weekly volume 20–30%.
A30: Session Types (Throw Log dropdown list)
A31: No Throw
A32: Long Toss
A33: Compression/Pulldowns
A34: Bullpen
A35: Moderate
A36: Game
A37: Recovery/Easy Catch
A40: Throw Rate by Session Type (throws/minute — used to estimate throw count from clock time)
A41: Timing a whole staff is far more practical than counting every throw. Log Start/End time in Throw Log and it estimates throw count as Duration × this rate. These are starting assumptions, not measured constants — clock a few reps of your own guys and tune them here. For a rehab player or anyone you CAN count exactly, just type the real number into Actual Throw Count in Throw Log and it overrides the time estimate automatically.
A43: Session Type | B43: Throw Rate (throws/min) | C43: Why
A44: No Throw | B44: 0
A45: Long Toss | B45: 3.5 | C45: Slower — ball travel + retrieval time grows with distance
A46: Compression/Pulldowns | B46: 3 | C46: High effort throws need more recovery between reps
A47: Bullpen | B47: 2.5 | C47: Reset, mechanics cues, and coach feedback between pitches
A48: Moderate | B48: 4 | C48: Moderate tempo, minimal reset time
A49: Game | B49: 0 | C49: Use actual pitch count, not a time estimate
...

Sheet Roster
A1: Roster — Velocity Reference
A2: Blue cells = edit these. Add every player who throws. Avg Top Velo (not Peak Velo) drives the Intensity Factor in Throw Log — it's the average of several of his hardest, most competitive readings (a max-effort bullpen, his best few readings across recent outings), not the single fastest pitch he's ever thrown. A one-time peak is noisy; an average of his real top gear is a more reliable “100% intent” line. Peak Velo is kept for reference only and isn't used in any calculation.
A4: Player Name | B4: Position/Role | C4: Peak Velo (mph) (reference only) | D4: Avg Top Velo (mph) (used in calc) | E4: Notes
A5: Adam Arther | B5: LHP | C5: 92.2 | D5: 87.9
A6: Lewis | D6: 91 | E6: Build-Up Plan: catch play Oct 12, first pen Jan 4
A7: Doty | D7: 91 | E7: Build-Up Plan: catch play Oct 12, first pen Jan 4
A8: Dean | D8: 89 | E8: Build-Up Plan: catch play Oct 12, first pen Jan 4

Sheet Throw Log
A1: Throw Log
A2: One row per throwing SET for most sessions (e.g. a long-toss step, a round of pulldowns). For the whole staff, log Start/End Time — throw count is estimated from that segment's pace (Reference tab); for a rehab guy or a bullpen (easy to count exactly), put the real number in Actual Throw Count and it overrides the time estimate. Enter Velo as a range (Velo Low–High, e.g. 70–74) — the midpoint is used for the calc. For Session Type “Bullpen” or “Game,” leave Distance blank — mound work uses a flat Mound Factor instead (Reference tab). GAME DAYS get ONE row, not two: fill columns H–L for the live outing (pitches + entering/between-innings warm-up, per the Reference callout) and use the Warmup/Bullpen columns (R–T) on that SAME row for whatever he threw getting loose in the pen beforehand — it's added into that row's Set Workload automatically at the Bullpen Mound Factor. Any day that closes by working back in at 60' gets the same treatment: use the 60' Throws / 60' Velo columns (X–Z) on that same row instead of a second row. BACK-TO-BACK: a Bullpen/Game row the day after another outing has its whole Set Workload multiplied (×1.5 by default); with one day in between, ×1.25 — Set Workload turns red/yellow when that happens, and columns AF–AG show the multiplier and the before-multiplier number (tune both on the Reference tab) — they're added in at the flat 60' Distance Factor. LONG TOSS: log it as ONE row — Distance = the farthest he got, Actual Throw Count = total throws for the whole step-out. It's scored as the standard step-out (90, 120, 150… every 30 ft up to that distance, more throws at the short steps), the same way the Build-Up tabs and Day Type Templates plan it. Blue cells = your input; everything else calculates automatically.
A4: Date | B4: Player | C4: Session Type | D4: Distance (ft) (n/a for Bullpen/Game) | E4: Start Time | F4: End Time | G4: Duration (min) | H4: Actual Throw Count (optional override) | I4: Throws Used in Calc | J4: Velo Low (mph) | K4: Velo High (mph) | L4: Velo Mid (mph) | M4: Player Avg Top Velo | N4: Velo Deficit (mph below avg) | O4: Distance/Mound Factor | P4: Intensity Factor | Q4: Set Workload (main + warmup + 60', × back-to-back) | R4: Warmup/Bullpen Throws (same day, optional) | S4: Warmup Velo Low | T4: Warmup Velo High | U4: Warmup Velo Mid | V4: Warmup Deficit | W4: Warmup Intensity Factor | X4: 60' Throws (working back in, optional) | Y4: 60' Velo Low | Z4: 60' Velo High | AA4: 60' Velo Mid | AB4: 60' Deficit | AC4: 60' Intensity Factor | AD4: Notes (arm feel, RPE, etc.) | AE4: Long-Toss Steps (auto) | AF4: Back-to-Back Multiplier | AG4: Workload Before Multiplier
A5: 46265 | B5: Adam Arther | C5: Moderate | D5: 120 | E5: 0.075694444 | F5: 0.085416667 | G5: =IF(OR(E5="",F5=""),"",(F5-E5)*1440) -> 14 | I5: =IF(H5<>"",H5,IF(G5="","",ROUND(G5*IFERROR(INDEX(Reference!$B$44:$B$50,MATCH(C5,Reference!$A$44:$A$50,0)),0),0))) -> 56 | J5: 75 | K5: 81 | L5: =IF(J5="","",IF(K5="",J5,AVERAGE(J5,K5))) -> 78 | M5: =IFERROR(INDEX(Roster!$D$5:$D$40,MATCH(B5,Roster!$A$5:$A$40,0)),"") -> 87.9 | N5: =IF(OR(L5="",M5="",M5=0),"",M5-L5) -> 9.9 | O5: =IF(OR(C5="Bullpen",C5="Game"),IFERROR(INDEX(Reference!$B$61:$B$62,MATCH(C5,Reference!$A$61:$A$62,0)),""),IF(D5="","",IF(AE5>1,((IF(1<=AE5,(AE5-1+3)*(INDEX(Reference!$B$6:$B$11,MIN(5,MATCH(MAX(Reference!$A$6,MIN(Reference!$A$11,MIN(D5,90))),Reference!$A$6:$A$11,1)))+(MAX(Reference!$A$6,MIN(Reference!$A$11,MIN(D5,90)))-INDEX(Reference!$A$6:$A$11,MIN(5,MATCH(MAX(Reference!$A$6,MIN(Reference!$A$11,MIN(D5,90))),Reference!$A$6:$A$11,1))))*(INDEX(Reference!$B$6:$B$11,MIN(5,MATCH(MAX(Reference!$A$6,MIN(Reference!$A$11,MIN(D5,90))),Reference!$A$6:$A$11,1))+1)-INDEX(Reference!$B$6:$B$11,MIN(5,MATCH(MAX(Reference!$A$6,MIN(Reference!$A$11,MIN(D5,90))),Reference!$A$6:$A$11,1))))/(INDEX(Reference!$A$6:$A$11,MIN(5,MATCH(MAX(Reference!$A$6,MIN(Reference!$A$11,MIN(D5,90))),Reference!$A$6:$A$11,1))+1)-INDEX(Reference!$A$6:$A$11,MIN(5,MATCH(MAX(Reference!$A$6,MIN(Reference!$A$11,MIN(D5,90))),Reference!$A$6:$A$11,1))))),0)+IF(2<=AE5,(AE5-2+3)*(INDEX(Reference!$B$6:$B$11,MIN(5,MATCH(MAX(Reference!$A$6,MIN(Reference!$A$11,MIN(D5,120))),Reference!$A$6:$A$11,1)))+(MAX(Reference!$A$6,MIN(Reference!$A$11,MIN(D5,120)))-INDEX(Reference!$A$6:$A$11,MIN(5,MATCH(MAX(Reference!$A$6,MIN(Reference!$A$11,MIN(D5,120))),Reference!$A$6:$A$11,1))))*(INDEX(Reference!$B$6:$B$11,MIN(5,MATCH(MAX(Reference!$A$6,MIN(Reference!$A$11,MIN(D5,120))),Reference!$A$6:$A$11,1))+1)-INDEX(Reference!$B$6:$B$11,MIN(5,MATCH(MAX(Reference!$A$6,MIN(Reference!$A$11,MIN(D5,120))),Reference!$A$6:$A$11,1))))/(INDEX(Reference!$A$6:$A$11,MIN(5,MATCH(MAX(Reference!$A$6,MIN(Reference!$A$11,MIN(D5,120))),Reference!$A$6:$A$11,1))+1)-INDEX(Reference!$A$6:$A$11,MIN(5,MATCH(MAX(Reference!$A$6,MIN(Reference!$A$11,MIN(D5,120))),Reference!$A$6:$A$11,1))))),0)+IF(3<=AE5,(AE5-3+3)*(INDEX(Reference!$B$6:$B$11,MIN(5,MATCH(MAX(Reference!$A$6,MIN(Reference!$A$11,MIN(D5,150))),Reference!$A$6:$A$11,1)))+(MAX(Reference!$A$6,MIN(Reference!$A$11,MIN(D5,150)))-INDEX(Reference!$A$6:$A$11,MIN(5,MATCH(MAX(Reference!$A$6,MIN(Reference!$A$11,MIN(D5,150))),Reference!$A$6:$A$11,1))))*(INDEX(Reference!$B$6:$B$11,MIN(5,MATCH(MAX(Reference!$A$6,MIN(Reference!$A$11,MIN(D5,150))),Reference!$A$6:$A$11,1))+1)-INDEX(Reference!$B$6:$B$11,MIN(5,MATCH(MAX(Reference!$A$6,MIN(Reference!$A$11,MIN(D5,150))),Reference!$A$6:$A$11,1))))/(INDEX(Reference!$A$6:$A$11,MIN(5,MATCH(MAX(Reference!$A$6,MIN(Reference!$A$11,MIN(D5,150))),Reference!$A$6:$A$11,1))+1)-INDEX(Reference!$A$6:$A$11,MIN(5,MATCH(MAX(Reference!$A$6,MIN(Reference!$A$11,MIN(D5,150))),Reference!$A$6:$A$11,1))))),0)+IF(4<=AE5,(AE5-4+3)*(INDEX(Reference!$B$6:$B$11,MIN(5,MATCH(MAX(Reference!$A$6,MIN(Reference!$A$11,MIN(D5,180))),Reference!$A$6:$A$11,1)))+(MAX(Reference!$A$6,MIN(Reference!$A$11,MIN(D5,180)))-INDEX(Reference!$A$6:$A$11,MIN(5,MATCH(MAX(Reference!$A$6,MIN(Reference!$A$11,MIN(D5,180))),Reference!$A$6:$A$11,1))))*(INDEX(Reference!$B$6:$B$11,MIN(5,MATCH(MAX(Reference!$A$6,MIN(Reference!$A$11,MIN(D5,180))),Reference!$A$6:$A$11,1))+1)-INDEX(Reference!$B$6:$B$11,MIN(5,MATCH(MAX(Reference!$A$6,MIN(Reference!$A$11,MIN(D5,180))),Reference!$A$6:$A$11,1))))/(INDEX(Reference!$A$6:$A$11,MIN(5,MATCH(MAX(Reference!$A$6,MIN(Reference!$A$11,MIN(D5,180))),Reference!$A$6:$A$11,1))+1)-INDEX(Reference!$A$6:$A$11,MIN(5,MATCH(MAX(Reference!$A$6,MIN(Reference!$A$11,MIN(D5,180))),Reference!$A$6:$A$11,1))))),0)+IF(5<=AE5,(AE5-5+3)*(INDEX(Reference!$B$6:$B$11,MIN(5,MATCH(MAX(Reference!$A$6,MIN(Reference!$A$11,MIN(D5,210))),Reference!$A$6:$A$11,1)))+(MAX(Reference!$A$6,MIN(Reference!$A$11,MIN(D5,210)))-INDEX(Reference!$A$6:$A$11,MIN(5,MATCH(MAX(Reference!$A$6,MIN(Reference!$A$11,MIN(D5,210))),Reference!$A$6:$A$11,1))))*(INDEX(Reference!$B$6:$B$11,MIN(5,MATCH(MAX(Reference!$A$6,MIN(Reference!$A$11,MIN(D5,210))),Reference!$A$6:$A$11,1))+1)-INDEX(Reference!$B$6:$B$11,MIN(5,MATCH(MAX(Reference!$A$6,MIN(Reference!$A$11,MIN(D5,210))),Reference!$A$6:$A$11,1))))/(INDEX(Reference!$A$6:$A$11,MIN(5,MATCH(MAX(Reference!$A$6,MIN(Reference!$A$11,MIN(D5,210))),Reference!$A$6:$A$11,1))+1)-INDEX(Reference!$A$6:$A$11,MIN(5,MATCH(MAX(Reference!$A$6,MIN(Reference!$A$11,MIN(D5,210))),Reference!$A$6:$A$11,1))))),0)+IF(6<=AE5,(AE5-6+3)*(INDEX(Reference!$B$6:$B$11,MIN(5,MATCH(MAX(Reference!$A$6,MIN(Reference!$A$11,MIN(D5,240))),Reference!$A$6:$A$11,1)))+(MAX(Reference!$A$6,MIN(Reference!$A$11,MIN(D5,240)))-INDEX(Reference!$A$6:$A$11,MIN(5,MATCH(MAX(Reference!$A$6,MIN(Reference!$A$11,MIN(D5,240))),Reference!$A$6:$A$11,1))))*(INDEX(Reference!$B$6:$B$11,MIN(5,MATCH(MAX(Reference!$A$6,MIN(Reference!$A$11,MIN(D5,240))),Reference!$A$6:$A$11,1))+1)-INDEX(Reference!$B$6:$B$11,MIN(5,MATCH(MAX(Reference!$A$6,MIN(Reference!$A$11,MIN(D5,240))),Reference!$A$6:$A$11,1))))/(INDEX(Reference!$A$6:$A$11,MIN(5,MATCH(MAX(Reference!$A$6,MIN(Reference!$A$11,MIN(D5,240))),Reference!$A$6:$A$11,1))+1)-INDEX(Reference!$A$6:$A$11,MIN(5,MATCH(MAX(Reference!$A$6,MIN(Reference!$A$11,MIN(D5,240))),Reference!$A$6:$A$11,1))))),0)+IF(7<=AE5,(AE5-7+3)*(INDEX(Reference!$B$6:$B$11,MIN(5,MATCH(MAX(Reference!$A$6,MIN(Reference!$A$11,MIN(D5,270))),Reference!$A$6:$A$11,1)))+(MAX(Reference!$A$6,MIN(Reference!$A$11,MIN(D5,270)))-INDEX(Reference!$A$6:$A$11,MIN(5,MATCH(MAX(Reference!$A$6,MIN(Reference!$A$11,MIN(D5,270))),Reference!$A$6:$A$11,1))))*(INDEX(Reference!$B$6:$B$11,MIN(5,MATCH(MAX(Reference!$A$6,MIN(Reference!$A$11,MIN(D5,270))),Reference!$A$6:$A$11,1))+1)-INDEX(Reference!$B$6:$B$11,MIN(5,MATCH(MAX(Reference!$A$6,MIN(Reference!$A$11,MIN(D5,270))),Reference!$A$6:$A$11,1))))/(INDEX(Reference!$A$6:$A$11,MIN(5,MATCH(MAX(Reference!$A$6,MIN(Reference!$A$11,MIN(D5,270))),Reference!$A$6:$A$11,1))+1)-INDEX(Reference!$A$6:$A$11,MIN(5,MATCH(MAX(Reference!$A$6,MIN(Reference!$A$11,MIN(D5,270))),Reference!$A$6:$A$11,1))))),0)+IF(8<=AE5,(AE5-8+3)*(INDEX(Reference!$B$6:$B$11,MIN(5,MATCH(MAX(Reference!$A$6,MIN(Reference!$A$11,MIN(D5,300))),Reference!$A$6:$A$11,1)))+(MAX(Reference!$A$6,MIN(Reference!$A$11,MIN(D5,300)))-INDEX(Reference!$A$6:$A$11,MIN(5,MATCH(MAX(Reference!$A$6,MIN(Reference!$A$11,MIN(D5,300))),Reference!$A$6:$A$11,1))))*(INDEX(Reference!$B$6:$B$11,MIN(5,MATCH(MAX(Reference!$A$6,MIN(Reference!$A$11,MIN(D5,300))),Reference!$A$6:$A$11,1))+1)-INDEX(Reference!$B$6:$B$11,MIN(5,MATCH(MAX(Reference!$A$6,MIN(Reference!$A$11,MIN(D5,300))),Reference!$A$6:$A$11,1))))/(INDEX(Reference!$A$6:$A$11,MIN(5,MATCH(MAX(Reference!$A$6,MIN(Reference!$A$11,MIN(D5,300))),Reference!$A$6:$A$11,1))+1)-INDEX(Reference!$A$6:$A$11,MIN(5,MATCH(MAX(Reference!$A$6,MIN(Reference!$A$11,MIN(D5,300))),Reference!$A$6:$A$11,1))))),0))/(AE5*(AE5+5)/2)),(INDEX(Reference!$B$6:$B$11,MIN(5,MATCH(MAX(Reference!$A$6,MIN(Reference!$A$11,D5)),Reference!$A$6:$A$11,1)))+(MAX(Reference!$A$6,MIN(Reference!$A$11,D5))-INDEX(Reference!$A$6:$A$11,MIN(5,MATCH(MAX(Reference!$A$6,MIN(Reference!$A$11,D5)),Reference!$A$6:$A$11,1))))*(INDEX(Reference!$B$6:$B$11,MIN(5,MATCH(MAX(Reference!$A$6,MIN(Reference!$A$11,D5)),Reference!$A$6:$A$11,1))+1)-INDEX(Reference!$B$6:$B$11,MIN(5,MATCH(MAX(Reference!$A$6,MIN(Reference!$A$11,D5)),Reference!$A$6:$A$11,1))))/(INDEX(Reference!$A$6:$A$11,MIN(5,MATCH(MAX(Reference!$A$6,MIN(Reference!$A$11,D5)),Reference!$A$6:$A$11,1))+1)-INDEX(Reference!$A$6:$A$11,MIN(5,MATCH(MAX(Reference!$A$6,MIN(Reference!$A$11,D5)),Reference!$A$6:$A$11,1)))))))) -> 1.7 | P5: =IF(N5="","",VLOOKUP(MAX(N5,0),Reference!$A$17:$B$20,2,TRUE())) -> 1 | Q5: =IF(AG5="","",AG5*IF(AF5="",1,AF5)) -> 95.2 | U5: =IF(S5="","",IF(T5="",S5,AVERAGE(S5,T5))) | V5: =IF(OR(U5="",M5="",M5=0),"",M5-U5) | W5: =IF(V5="","",VLOOKUP(MAX(V5,0),Reference!$A$17:$B$20,2,TRUE())) | AA5: =IF(Y5="","",IF(Z5="",Y5,AVERAGE(Y5,Z5))) | AB5: =IF(OR(AA5="",M5="",M5=0),"",M5-AA5) | AC5: =IF(AB5="","",VLOOKUP(MAX(AB5,0),Reference!$A$17:$B$20,2,TRUE())) | AD5: Timed the whole group together | AE5: =IF(AND(C5="Long Toss",N(D5)>90),1+ROUNDUP((D5-90)/30,0),1) -> 1 | AF5: =IF(OR(A5="",B5="",AND(C5<>"Bullpen",C5<>"Game")),"",IF((COUNTIFS($B$5:$B$300,B5,$A$5:$A$300,A5-1,$C$5:$C$300,"Bullpen",$AG$5:$AG$300,">0") + COUNTIFS($B$5:$B$300,B5,$A$5:$A$300,A5-1,$C$5:$C$300,"Game",$AG$5:$AG$300,">0"))>0,Reference!$B$119,IF((COUNTIFS($B$5:$B$300,B5,$A$5:$A$300,A5-2,$C$5:$C$300,"Bullpen",$AG$5:$AG$300,">0") + COUNTIFS($B$5:$B$300,B5,$A$5:$A$300,A5-2,$C$5:$C$300,"Game",$AG$5:$AG$300,">0"))>0,Reference!$B$120,1))) | AG5: =IF(AND(OR(I5="",O5="",P5=""),OR(R5="",W5=""),OR(X5="",AC5="")),"",IF(OR(I5="",O5="",P5=""),0,I5*O5*P5)+IF(OR(R5="",W5=""),0,R5*IFERROR(INDEX(Reference!$B$61:$B$62,MATCH("Bullpen",Reference!$A$61:$A$62,0)),0)*W5)+IF(OR(X5="",AC5=""),0,X5*(INDEX(Reference!$B$6:$B$11,MIN(5,MATCH(MAX(Reference!$A$6,MIN(Reference!$A$11,60)),Reference!$A$6:$A$11,1)))+(MAX(Reference!$A$6,MIN(Reference!$A$11,60))-INDEX(Reference!$A$6:$A$11,MIN(5,MATCH(MAX(Reference!$A$6,MIN(Reference!$A$11,60)),Reference!$A$6:$A$11,1))))*(INDEX(Reference!$B$6:$B$11,MIN(5,MATCH(MAX(Reference!$A$6,MIN(Reference!$A$11,60)),Reference!$A$6:$A$11,1))+1)-INDEX(Reference!$B$6:$B$11,MIN(5,MATCH(MAX(Reference!$A$6,MIN(Reference!$A$11,60)),Reference!$A$6:$A$11,1))))/(INDEX(Reference!$A$6:$A$11,MIN(5,MATCH(MAX(Reference!$A$6,MIN(Reference!$A$11,60)),Reference!$A$6:$A$11,1))+1)-INDEX(Reference!$A$6:$A$11,MIN(5,MATCH(MAX(Reference!$A$6,MIN(Reference!$A$11,60)),Reference!$A$6:$A$11,1)))))*AC5)) -> 95.2
A6: 46266 | B6: Adam Arther | C6: Recovery/Easy Catch | D6: 75 | E6: 0.072916667 | F6: 0.08125 | G6: =IF(OR(E6="",F6=""),"",(F6-E6)*1440) -> 12 | I6: =IF(H6<>"",H6,IF(G6="","",ROUND(G6*IFERROR(INDEX(Reference!$B$44:$B$50,MATCH(C6,Reference!$A$44:$A$50,0)),0),0))) -> 66 | J6: 72 | K6: 75 | L6: =IF(J6="","",IF(K6="",J6,AVERAGE(J6,K6))) -> 73.5 | M6: =IFERROR(INDEX(Roster!$D$5:$D$40,MATCH(B6,Roster!$A$5:$A$40,0)),"") -> 87.9 | N6: =IF(OR(L6="",M6="",M6=0),"",M6-L6) -> 14.4 | O6: =IF(OR(C6="Bullpen",C6="Game"),IFERROR(INDEX(Reference!$B$61:$B$62,MATCH(C6,Reference!$A$61:$A$62,0)),""),IF(D6="","",IF(AE6>1,((IF(1<=AE6,(AE6-1+3)*(INDEX(Reference!$B$6:$B$11,MIN(5,MATCH(MAX(Reference!$A$6,MIN(Reference!$A$11,MIN(D6,90))),Reference!$A$6:$A$11,1)))+(MAX(Reference!$A$6,MIN(Reference!$A$11,MIN(D6,90)))-INDEX(Reference!$A$6:$A$11,MIN(5,MATCH(MAX(Reference!$A$6,MIN(Reference!$A$11,MIN(D6,90))),Reference!$A$6:$A$11,1))))*(INDEX(Reference!$B$6:$B$11,MIN(5,MATCH(MAX(Reference!$A$6,MIN(Reference!$A$11,MIN(D6,90))),Reference!$A$6:$A$11,1))+1)-INDEX(Reference!$B$6:$B$11,MIN(5,MATCH(MAX(Reference!$A$6,MIN(Reference!$A$11,MIN(D6,90))),Reference!$A$6:$A$11,1))))/(INDEX(Reference!$A$6:$A$11,MIN(5,MATCH(MAX(Reference!$A$6,MIN(Reference!$A$11,MIN(D6,90))),Reference!$A$6:$A$11,1))+1)-INDEX(Reference!$A$6:$A$11,MIN(5,MATCH(MAX(Reference!$A$6,MIN(Reference!$A$11,MIN(D6,90))),Reference!$A$6:$A$11,1))))),0)+IF(2<=AE6,(AE6-2+3)*(INDEX(Reference!$B$6:$B$11,MIN(5,MATCH(MAX(Reference!$A$6,MIN(Reference!$A$11,MIN(D6,120))),Reference!$A$6:$A$11,1)))+(MAX(Reference!$A$6,MIN(Reference!$A$11,MIN(D6,120)))-INDEX(Reference!$A$6:$A$11,MIN(5,MATCH(MAX(Reference!$A$6,MIN(Reference!$A$11,MIN(D6,120))),Reference!$A$6:$A$11,1))))*(INDEX(Reference!$B$6:$B$11,MIN(5,MATCH(MAX(Reference!$A$6,MIN(Reference!$A$11,MIN(D6,120))),Reference!$A$6:$A$11,1))+1)-INDEX(Reference!$B$6:$B$11,MIN(5,MATCH(MAX(Reference!$A$6,MIN(Reference!$A$11,MIN(D6,120))),Reference!$A$6:$A$11,1))))/(INDEX(Reference!$A$6:$A$11,MIN(5,MATCH(MAX(Reference!$A$6,MIN(Reference!$A$11,MIN(D6,120))),Reference!$A$6:$A$11,1))+1)-INDEX(Reference!$A$6:$A$11,MIN(5,MATCH(MAX(Reference!$A$6,MIN(Reference!$A$11,MIN(D6,120))),Reference!$A$6:$A$11,1))))),0)+IF(3<=AE6,(AE6-3+3)*(INDEX(Reference!$B$6:$B$11,MIN(5,MATCH(MAX(Reference!$A$6,MIN(Reference!$A$11,MIN(D6,150))),Reference!$A$6:$A$11,1)))+(MAX(Reference!$A$6,MIN(Reference!$A$11,MIN(D6,150)))-INDEX(Reference!$A$6:$A$11,MIN(5,MATCH(MAX(Reference!$A$6,MIN(Reference!$A$11,MIN(D6,150))),Reference!$A$6:$A$11,1))))*(INDEX(Reference!$B$6:$B$11,MIN(5,MATCH(MAX(Reference!$A$6,MIN(Reference!$A$11,MIN(D6,150))),Reference!$A$6:$A$11,1))+1)-INDEX(Reference!$B$6:$B$11,MIN(5,MATCH(MAX(Reference!$A$6,MIN(Reference!$A$11,MIN(D6,150))),Reference!$A$6:$A$11,1))))/(INDEX(Reference!$A$6:$A$11,MIN(5,MATCH(MAX(Reference!$A$6,MIN(Reference!$A$11,MIN(D6,150))),Reference!$A$6:$A$11,1))+1)-INDEX(Reference!$A$6:$A$11,MIN(5,MATCH(MAX(Reference!$A$6,MIN(Reference!$A$11,MIN(D6,150))),Reference!$A$6:$A$11,1))))),0)+IF(4<=AE6,(AE6-4+3)*(INDEX(Reference!$B$6:$B$11,MIN(5,MATCH(MAX(Reference!$A$6,MIN(Reference!$A$11,MIN(D6,180))),Reference!$A$6:$A$11,1)))+(MAX(Reference!$A$6,MIN(Reference!$A$11,MIN(D6,180)))-INDEX(Reference!$A$6:$A$11,MIN(5,MATCH(MAX(Reference!$A$6,MIN(Reference!$A$11,MIN(D6,180))),Reference!$A$6:$A$11,1))))*(INDEX(Reference!$B$6:$B$11,MIN(5,MATCH(MAX(Reference!$A$6,MIN(Reference!$A$11,MIN(D6,180))),Reference!$A$6:$A$11,1))+1)-INDEX(Reference!$B$6:$B$11,MIN(5,MATCH(MAX(Reference!$A$6,MIN(Reference!$A$11,MIN(D6,180))),Reference!$A$6:$A$11,1))))/(INDEX(Reference!$A$6:$A$11,MIN(5,MATCH(MAX(Reference!$A$6,MIN(Reference!$A$11,MIN(D6,180))),Reference!$A$6:$A$11,1))+1)-INDEX(Reference!$A$6:$A$11,MIN(5,MATCH(MAX(Reference!$A$6,MIN(Reference!$A$11,MIN(D6,180))),Reference!$A$6:$A$11,1))))),0)+IF(5<=AE6,(AE6-5+3)*(INDEX(Reference!$B$6:$B$11,MIN(5,MATCH(MAX(Reference!$A$6,MIN(Reference!$A$11,MIN(D6,210))),Reference!$A$6:$A$11,1)))+(MAX(Reference!$A$6,MIN(Reference!$A$11,MIN(D6,210)))-INDEX(Reference!$A$6:$A$11,MIN(5,MATCH(MAX(Reference!$A$6,MIN(Reference!$A$11,MIN(D6,210))),Reference!$A$6:$A$11,1))))*(INDEX(Reference!$B$6:$B$11,MIN(5,MATCH(MAX(Reference!$A$6,MIN(Reference!$A$11,MIN(D6,210))),Reference!$A$6:$A$11,1))+1)-INDEX(Reference!$B$6:$B$11,MIN(5,MATCH(MAX(Reference!$A$6,MIN(Reference!$A$11,MIN(D6,210))),Reference!$A$6:$A$11,1))))/(INDEX(Reference!$A$6:$A$11,MIN(5,MATCH(MAX(Reference!$A$6,MIN(Reference!$A$11,MIN(D6,210))),Reference!$A$6:$A$11,1))+1)-INDEX(Reference!$A$6:$A$11,MIN(5,MATCH(MAX(Reference!$A$6,MIN(Reference!$A$11,MIN(D6,210))),Reference!$A$6:$A$11,1))))),0)+IF(6<=AE6,(AE6-6+3)*(INDEX(Reference!$B$6:$B$11,MIN(5,MATCH(MAX(Reference!$A$6,MIN(Reference!$A$11,MIN(D6,240))),Reference!$A$6:$A$11,1)))+(MAX(Reference!$A$6,MIN(Reference!$A$11,MIN(D6,240)))-INDEX(Reference!$A$6:$A$11,MIN(5,MATCH(MAX(Reference!$A$6,MIN(Reference!$A$11,MIN(D6,240))),Reference!$A$6:$A$11,1))))*(INDEX(Reference!$B$6:$B$11,MIN(5,MATCH(MAX(Reference!$A$6,MIN(Reference!$A$11,MIN(D6,240))),Reference!$A$6:$A$11,1))+1)-INDEX(Reference!$B$6:$B$11,MIN(5,MATCH(MAX(Reference!$A$6,MIN(Reference!$A$11,MIN(D6,240))),Reference!$A$6:$A$11,1))))/(INDEX(Reference!$A$6:$A$11,MIN(5,MATCH(MAX(Reference!$A$6,MIN(Reference!$A$11,MIN(D6,240))),Reference!$A$6:$A$11,1))+1)-INDEX(Reference!$A$6:$A$11,MIN(5,MATCH(MAX(Reference!$A$6,MIN(Reference!$A$11,MIN(D6,240))),Reference!$A$6:$A$11,1))))),0)+IF(7<=AE6,(AE6-7+3)*(INDEX(Reference!$B$6:$B$11,MIN(5,MATCH(MAX(Reference!$A$6,MIN(Reference!$A$11,MIN(D6,270))),Reference!$A$6:$A$11,1)))+(MAX(Reference!$A$6,MIN(Reference!$A$11,MIN(D6,270)))-INDEX(Reference!$A$6:$A$11,MIN(5,MATCH(MAX(Reference!$A$6,MIN(Reference!$A$11,MIN(D6,270))),Reference!$A$6:$A$11,1))))*(INDEX(Reference!$B$6:$B$11,MIN(5,MATCH(MAX(Reference!$A$6,MIN(Reference!$A$11,MIN(D6,270))),Reference!$A$6:$A$11,1))+1)-INDEX(Reference!$B$6:$B$11,MIN(5,MATCH(MAX(Reference!$A$6,MIN(Reference!$A$11,MIN(D6,270))),Reference!$A$6:$A$11,1))))/(INDEX(Reference!$A$6:$A$11,MIN(5,MATCH(MAX(Reference!$A$6,MIN(Reference!$A$11,MIN(D6,270))),Reference!$A$6:$A$11,1))+1)-INDEX(Reference!$A$6:$A$11,MIN(5,MATCH(MAX(Reference!$A$6,MIN(Reference!$A$11,MIN(D6,270))),Reference!$A$6:$A$11,1))))),0)+IF(8<=AE6,(AE6-8+3)*(INDEX(Reference!$B$6:$B$11,MIN(5,MATCH(MAX(Reference!$A$6,MIN(Reference!$A$11,MIN(D6,300))),Reference!$A$6:$A$11,1)))+(MAX(Reference!$A$6,MIN(Reference!$A$11,MIN(D6,300)))-INDEX(Reference!$A$6:$A$11,MIN(5,MATCH(MAX(Reference!$A$6,MIN(Reference!$A$11,MIN(D6,300))),Reference!$A$6:$A$11,1))))*(INDEX(Reference!$B$6:$B$11,MIN(5,MATCH(MAX(Reference!$A$6,MIN(Reference!$A$11,MIN(D6,300))),Reference!$A$6:$A$11,1))+1)-INDEX(Reference!$B$6:$B$11,MIN(5,MATCH(MAX(Reference!$A$6,MIN(Reference!$A$11,MIN(D6,300))),Reference!$A$6:$A$11,1))))/(INDEX(Reference!$A$6:$A$11,MIN(5,MATCH(MAX(Reference!$A$6,MIN(Reference!$A$11,MIN(D6,300))),Reference!$A$6:$A$11,1))+1)-INDEX(Reference!$A$6:$A$11,MIN(5,MATCH(MAX(Reference!$A$6,MIN(Reference!$A$11,MIN(D6,300))),Reference!$A$6:$A$11,1))))),0))/(AE6*(AE6+5)/2)),(INDEX(Reference!$B$6:$B$11,MIN(5,MATCH(MAX(Reference!$A$6,MIN(Reference!$A$11,D6)),Reference!$A$6:$A$11,1)))+(MAX(Reference!$A$6,MIN(Reference!$A$11,D6))-INDEX(Reference!$A$6:$A$11,MIN(5,MATCH(MAX(Reference!$A$6,MIN(Reference!$A$11,D6)),Reference!$A$6:$A$11,1))))*(INDEX(Reference!$B$6:$B$11,MIN(5,MATCH(MAX(Reference!$A$6,MIN(Reference!$A$11,D6)),Reference!$A$6:$A$11,1))+1)-INDEX(Reference!$B$6:$B$11,MIN(5,MATCH(MAX(Reference!$A$6,MIN(Reference!$A$11,D6)),Reference!$A$6:$A$11,1))))/(INDEX(Reference!$A$6:$A$11,MIN(5,MATCH(MAX(Reference!$A$6,MIN(Reference!$A$11,D6)),Reference!$A$6:$A$11,1))+1)-INDEX(Reference!$A$6:$A$11,MIN(5,MATCH(MAX(Reference!$A$6,MIN(Reference!$A$11,D6)),Reference!$A$6:$A$11,1)))))))) -> 1.15 | P6: =IF(N6="","",VLOOKUP(MAX(N6,0),Reference!$A$17:$B$20,2,TRUE())) -> 0.6 | Q6: =IF(AG6="","",AG6*IF(AF6="",1,AF6)) -> 45.54 | U6: =IF(S6="","",IF(T6="",S6,AVERAGE(S6,T6))) | V6: =IF(OR(U6="",M6="",M6=0),"",M6-U6) | W6: =IF(V6="","",VLOOKUP(MAX(V6,0),Reference!$A$17:$B$20,2,TRUE())) | AA6: =IF(Y6="","",IF(Z6="",Y6,AVERAGE(Y6,Z6))) | AB6: =IF(OR(AA6="",M6="",M6=0),"",M6-AA6) | AC6: =IF(AB6="","",VLOOKUP(MAX(AB6,0),Reference!$A$17:$B$20,2,TRUE())) | AD6: WORKING BACK — stretching out to 150 ft, easy effort, estimated from time | AE6: =IF(AND(C6="Long Toss",N(D6)>90),1+ROUNDUP((D6-90)/30,0),1) -> 1 | AF6: =IF(OR(A6="",B6="",AND(C6<>"Bullpen",C6<>"Game")),"",IF((COUNTIFS($B$5:$B$300,B6,$A$5:$A$300,A6-1,$C$5:$C$300,"Bullpen",$AG$5:$AG$300,">0") + COUNTIFS($B$5:$B$300,B6,$A$5:$A$300,A6-1,$C$5:$C$300,"Game",$AG$5:$AG$300,">0"))>0,Reference!$B$119,IF((COUNTIFS($B$5:$B$300,B6,$A$5:$A$300,A6-2,$C$5:$C$300,"Bullpen",$AG$5:$AG$300,">0") + COUNTIFS($B$5:$B$300,B6,$A$5:$A$300,A6-2,$C$5:$C$300,"Game",$AG$5:$AG$300,">0"))>0,Reference!$B$120,1))) | AG6: =IF(AND(OR(I6="",O6="",P6=""),OR(R6="",W6=""),OR(X6="",AC6="")),"",IF(OR(I6="",O6="",P6=""),0,I6*O6*P6)+IF(OR(R6="",W6=""),0,R6*IFERROR(INDEX(Reference!$B$61:$B$62,MATCH("Bullpen",Reference!$A$61:$A$62,0)),0)*W6)+IF(OR(X6="",AC6=""),0,X6*(INDEX(Reference!$B$6:$B$11,MIN(5,MATCH(MAX(Reference!$A$6,MIN(Reference!$A$11,60)),Reference!$A$6:$A$11,1)))+(MAX(Reference!$A$6,MIN(Reference!$A$11,60))-INDEX(Reference!$A$6:$A$11,MIN(5,MATCH(MAX(Reference!$A$6,MIN(Reference!$A$11,60)),Reference!$A$6:$A$11,1))))*(INDEX(Reference!$B$6:$B$11,MIN(5,MATCH(MAX(Reference!$A$6,MIN(Reference!$A$11,60)),Reference!$A$6:$A$11,1))+1)-INDEX(Reference!$B$6:$B$11,MIN(5,MATCH(MAX(Reference!$A$6,MIN(Reference!$A$11,60)),Reference!$A$6:$A$11,1))))/(INDEX(Reference!$A$6:$A$11,MIN(5,MATCH(MAX(Reference!$A$6,MIN(Reference!$A$11,60)),Reference!$A$6:$A$11,1))+1)-INDEX(Reference!$A$6:$A$11,MIN(5,MATCH(MAX(Reference!$A$6,MIN(Reference!$A$11,60)),Reference!$A$6:$A$11,1)))))*AC6)) -> 45.54
A7: 46267 | B7: Adam Arther | C7: Moderate | D7: 120 | E7: 0.075694444 | F7: 0.085416667 | G7: =IF(OR(E7="",F7=""),"",(F7-E7)*1440) -> 14 | I7: =IF(H7<>"",H7,IF(G7="","",ROUND(G7*IFERROR(INDEX(Reference!$B$44:$B$50,MATCH(C7,Reference!$A$44:$A$50,0)),0),0))) -> 56 | J7: 75 | K7: 81 | L7: =IF(J7="","",IF(K7="",J7,AVERAGE(J7,K7))) -> 78 | M7: =IFERROR(INDEX(Roster!$D$5:$D$40,MATCH(B7,Roster!$A$5:$A$40,0)),"") -> 87.9 | N7: =IF(OR(L7="",M7="",M7=0),"",M7-L7) -> 9.9 | O7: =IF(OR(C7="Bullpen",C7="Game"),IFERROR(INDEX(Reference!$B$61:$B$62,MATCH(C7,Reference!$A$61:$A$62,0)),""),IF(D7="","",IF(AE7>1,((IF(1<=AE7,(AE7-1+3)*(INDEX(Reference!$B$6:$B$11,MIN(5,MATCH(MAX(Reference!$A$6,MIN(Reference!$A$11,MIN(D7,90))),Reference!$A$6:$A$11,1)))+(MAX(Reference!$A$6,MIN(Reference!$A$11,MIN(D7,90)))-INDEX(Reference!$A$6:$A$11,MIN(5,MATCH(MAX(Reference!$A$6,MIN(Reference!$A$11,MIN(D7,90))),Reference!$A$6:$A$11,1))))*(INDEX(Reference!$B$6:$B$11,MIN(5,MATCH(MAX(Reference!$A$6,MIN(Reference!$A$11,MIN(D7,90))),Reference!$A$6:$A$11,1))+1)-INDEX(Reference!$B$6:$B$11,MIN(5,MATCH(MAX(Reference!$A$6,MIN(Reference!$A$11,MIN(D7,90))),Reference!$A$6:$A$11,1))))/(INDEX(Reference!$A$6:$A$11,MIN(5,MATCH(MAX(Reference!$A$6,MIN(Reference!$A$11,MIN(D7,90))),Reference!$A$6:$A$11,1))+1)-INDEX(Reference!$A$6:$A$11,MIN(5,MATCH(MAX(Reference!$A$6,MIN(Reference!$A$11,MIN(D7,90))),Reference!$A$6:$A$11,1))))),0)+IF(2<=AE7,(AE7-2+3)*(INDEX(Reference!$B$6:$B$11,MIN(5,MATCH(MAX(Reference!$A$6,MIN(Reference!$A$11,MIN(D7,120))),Reference!$A$6:$A$11,1)))+(MAX(Reference!$A$6,MIN(Reference!$A$11,MIN(D7,120)))-INDEX(Reference!$A$6:$A$11,MIN(5,MATCH(MAX(Reference!$A$6,MIN(Reference!$A$11,MIN(D7,120))),Reference!$A$6:$A$11,1))))*(INDEX(Reference!$B$6:$B$11,MIN(5,MATCH(MAX(Reference!$A$6,MIN(Reference!$A$11,MIN(D7,120))),Reference!$A$6:$A$11,1))+1)-INDEX(Reference!$B$6:$B$11,MIN(5,MATCH(MAX(Reference!$A$6,MIN(Reference!$A$11,MIN(D7,120))),Reference!$A$6:$A$11,1))))/(INDEX(Reference!$A$6:$A$11,MIN(5,MATCH(MAX(Reference!$A$6,MIN(Reference!$A$11,MIN(D7,120))),Reference!$A$6:$A$11,1))+1)-INDEX(Reference!$A$6:$A$11,MIN(5,MATCH(MAX(Reference!$A$6,MIN(Reference!$A$11,MIN(D7,120))),Reference!$A$6:$A$11,1))))),0)+IF(3<=AE7,(AE7-3+3)*(INDEX(Reference!$B$6:$B$11,MIN(5,MATCH(MAX(Reference!$A$6,MIN(Reference!$A$11,MIN(D7,150))),Reference!$A$6:$A$11,1)))+(MAX(Reference!$A$6,MIN(Reference!$A$11,MIN(D7,150)))-INDEX(Reference!$A$6:$A$11,MIN(5,MATCH(MAX(Reference!$A$6,MIN(Reference!$A$11,MIN(D7,150))),Reference!$A$6:$A$11,1))))*(INDEX(Reference!$B$6:$B$11,MIN(5,MATCH(MAX(Reference!$A$6,MIN(Reference!$A$11,MIN(D7,150))),Reference!$A$6:$A$11,1))+1)-INDEX(Reference!$B$6:$B$11,MIN(5,MATCH(MAX(Reference!$A$6,MIN(Reference!$A$11,MIN(D7,150))),Reference!$A$6:$A$11,1))))/(INDEX(Reference!$A$6:$A$11,MIN(5,MATCH(MAX(Reference!$A$6,MIN(Reference!$A$11,MIN(D7,150))),Reference!$A$6:$A$11,1))+1)-INDEX(Reference!$A$6:$A$11,MIN(5,MATCH(MAX(Reference!$A$6,MIN(Reference!$A$11,MIN(D7,150))),Reference!$A$6:$A$11,1))))),0)+IF(4<=AE7,(AE7-4+3)*(INDEX(Reference!$B$6:$B$11,MIN(5,MATCH(MAX(Reference!$A$6,MIN(Reference!$A$11,MIN(D7,180))),Reference!$A$6:$A$11,1)))+(MAX(Reference!$A$6,MIN(Reference!$A$11,MIN(D7,180)))-INDEX(Reference!$A$6:$A$11,MIN(5,MATCH(MAX(Reference!$A$6,MIN(Reference!$A$11,MIN(D7,180))),Reference!$A$6:$A$11,1))))*(INDEX(Reference!$B$6:$B$11,MIN(5,MATCH(MAX(Reference!$A$6,MIN(Reference!$A$11,MIN(D7,180))),Reference!$A$6:$A$11,1))+1)-INDEX(Reference!$B$6:$B$11,MIN(5,MATCH(MAX(Reference!$A$6,MIN(Reference!$A$11,MIN(D7,180))),Reference!$A$6:$A$11,1))))/(INDEX(Reference!$A$6:$A$11,MIN(5,MATCH(MAX(Reference!$A$6,MIN(Reference!$A$11,MIN(D7,180))),Reference!$A$6:$A$11,1))+1)-INDEX(Reference!$A$6:$A$11,MIN(5,MATCH(MAX(Reference!$A$6,MIN(Reference!$A$11,MIN(D7,180))),Reference!$A$6:$A$11,1))))),0)+IF(5<=AE7,(AE7-5+3)*(INDEX(Reference!$B$6:$B$11,MIN(5,MATCH(MAX(Reference!$A$6,MIN(Reference!$A$11,MIN(D7,210))),Reference!$A$6:$A$11,1)))+(MAX(Reference!$A$6,MIN(Reference!$A$11,MIN(D7,210)))-INDEX(Reference!$A$6:$A$11,MIN(5,MATCH(MAX(Reference!$A$6,MIN(Reference!$A$11,MIN(D7,210))),Reference!$A$6:$A$11,1))))*(INDEX(Reference!$B$6:$B$11,MIN(5,MATCH(MAX(Reference!$A$6,MIN(Reference!$A$11,MIN(D7,210))),Reference!$A$6:$A$11,1))+1)-INDEX(Reference!$B$6:$B$11,MIN(5,MATCH(MAX(Reference!$A$6,MIN(Reference!$A$11,MIN(D7,210))),Reference!$A$6:$A$11,1))))/(INDEX(Reference!$A$6:$A$11,MIN(5,MATCH(MAX(Reference!$A$6,MIN(Reference!$A$11,MIN(D7,210))),Reference!$A$6:$A$11,1))+1)-INDEX(Reference!$A$6:$A$11,MIN(5,MATCH(MAX(Reference!$A$6,MIN(Reference!$A$11,MIN(D7,210))),Reference!$A$6:$A$11,1))))),0)+IF(6<=AE7,(AE7-6+3)*(INDEX(Reference!$B$6:$B$11,MIN(5,MATCH(MAX(Reference!$A$6,MIN(Reference!$A$11,MIN(D7,240))),Reference!$A$6:$A$11,1)))+(MAX(Reference!$A$6,MIN(Reference!$A$11,MIN(D7,240)))-INDEX(Reference!$A$6:$A$11,MIN(5,MATCH(MAX(Reference!$A$6,MIN(Reference!$A$11,MIN(D7,240))),Reference!$A$6:$A$11,1))))*(INDEX(Reference!$B$6:$B$11,MIN(5,MATCH(MAX(Reference!$A$6,MIN(Reference!$A$11,MIN(D7,240))),Reference!$A$6:$A$11,1))+1)-INDEX(Reference!$B$6:$B$11,MIN(5,MATCH(MAX(Reference!$A$6,MIN(Reference!$A$11,MIN(D7,240))),Reference!$A$6:$A$11,1))))/(INDEX(Reference!$A$6:$A$11,MIN(5,MATCH(MAX(Reference!$A$6,MIN(Reference!$A$11,MIN(D7,240))),Reference!$A$6:$A$11,1))+1)-INDEX(Reference!$A$6:$A$11,MIN(5,MATCH(MAX(Reference!$A$6,MIN(Reference!$A$11,MIN(D7,240))),Reference!$A$6:$A$11,1))))),0)+IF(7<=AE7,(AE7-7+3)*(INDEX(Reference!$B$6:$B$11,MIN(5,MATCH(MAX(Reference!$A$6,MIN(Reference!$A$11,MIN(D7,270))),Reference!$A$6:$A$11,1)))+(MAX(Reference!$A$6,MIN(Reference!$A$11,MIN(D7,270)))-INDEX(Reference!$A$6:$A$11,MIN(5,MATCH(MAX(Reference!$A$6,MIN(Reference!$A$11,MIN(D7,270))),Reference!$A$6:$A$11,1))))*(INDEX(Reference!$B$6:$B$11,MIN(5,MATCH(MAX(Reference!$A$6,MIN(Reference!$A$11,MIN(D7,270))),Reference!$A$6:$A$11,1))+1)-INDEX(Reference!$B$6:$B$11,MIN(5,MATCH(MAX(Reference!$A$6,MIN(Reference!$A$11,MIN(D7,270))),Reference!$A$6:$A$11,1))))/(INDEX(Reference!$A$6:$A$11,MIN(5,MATCH(MAX(Reference!$A$6,MIN(Reference!$A$11,MIN(D7,270))),Reference!$A$6:$A$11,1))+1)-INDEX(Reference!$A$6:$A$11,MIN(5,MATCH(MAX(Reference!$A$6,MIN(Reference!$A$11,MIN(D7,270))),Reference!$A$6:$A$11,1))))),0)+IF(8<=AE7,(AE7-8+3)*(INDEX(Reference!$B$6:$B$11,MIN(5,MATCH(MAX(Reference!$A$6,MIN(Reference!$A$11,MIN(D7,300))),Reference!$A$6:$A$11,1)))+(MAX(Reference!$A$6,MIN(Reference!$A$11,MIN(D7,300)))-INDEX(Reference!$A$6:$A$11,MIN(5,MATCH(MAX(Reference!$A$6,MIN(Reference!$A$11,MIN(D7,300))),Reference!$A$6:$A$11,1))))*(INDEX(Reference!$B$6:$B$11,MIN(5,MATCH(MAX(Reference!$A$6,MIN(Reference!$A$11,MIN(D7,300))),Reference!$A$6:$A$11,1))+1)-INDEX(Reference!$B$6:$B$11,MIN(5,MATCH(MAX(Reference!$A$6,MIN(Reference!$A$11,MIN(D7,300))),Reference!$A$6:$A$11,1))))/(INDEX(Reference!$A$6:$A$11,MIN(5,MATCH(MAX(Reference!$A$6,MIN(Reference!$A$11,MIN(D7,300))),Reference!$A$6:$A$11,1))+1)-INDEX(Reference!$A$6:$A$11,MIN(5,MATCH(MAX(Reference!$A$6,MIN(Reference!$A$11,MIN(D7,300))),Reference!$A$6:$A$11,1))))),0))/(AE7*(AE7+5)/2)),(INDEX(Reference!$B$6:$B$11,MIN(5,MATCH(MAX(Reference!$A$6,MIN(Reference!$A$11,D7)),Reference!$A$6:$A$11,1)))+(MAX(Reference!$A$6,MIN(Reference!$A$11,D7))-INDEX(Reference!$A$6:$A$11,MIN(5,MATCH(MAX(Reference!$A$6,MIN(Reference!$A$11,D7)),Reference!$A$6:$A$11,1))))*(INDEX(Reference!$B$6:$B$11,MIN(5,MATCH(MAX(Reference!$A$6,MIN(Reference!$A$11,D7)),Reference!$A$6:$A$11,1))+1)-INDEX(Reference!$B$6:$B$11,MIN(5,MATCH(MAX(Reference!$A$6,MIN(Reference!$A$11,D7)),Reference!$A$6:$A$11,1))))/(INDEX(Reference!$A$6:$A$11,MIN(5,MATCH(MAX(Reference!$A$6,MIN(Reference!$A$11,D7)),Reference!$A$6:$A$11,1))+1)-INDEX(Reference!$A$6:$A$11,MIN(5,MATCH(MAX(Reference!$A$6,MIN(Reference!$A$11,D7)),Reference!$A$6:$A$11,1)))))))) -> 1.7 | P7: =IF(N7="","",VLOOKUP(MAX(N7,0),Reference!$A$17:$B$20,2,TRUE())) -> 1 | Q7: =IF(AG7="","",AG7*IF(AF7="",1,AF7)) -> 95.2 | U7: =IF(S7="","",IF(T7="",S7,AVERAGE(S7,T7))) | V7: =IF(OR(U7="",M7="",M7=0),"",M7-U7) | W7: =IF(V7="","",VLOOKUP(MAX(V7,0),Reference!$A$17:$B$20,2,TRUE())) | AA7: =IF(Y7="","",IF(Z7="",Y7,AVERAGE(Y7,Z7))) | AB7: =IF(OR(AA7="",M7="",M7=0),"",M7-AA7) | AC7: =IF(AB7="","",VLOOKUP(MAX(AB7,0),Reference!$A$17:$B$20,2,TRUE())) | AD7: WORKING IN — compression at 90 ft; radar-gunned so exact count overrides the time estimate | AE7: =IF(AND(C7="Long Toss",N(D7)>90),1+ROUNDUP((D7-90)/30,0),1) -> 1 | AF7: =IF(OR(A7="",B7="",AND(C7<>"Bullpen",C7<>"Game")),"",IF((COUNTIFS($B$5:$B$300,B7,$A$5:$A$300,A7-1,$C$5:$C$300,"Bullpen",$AG$5:$AG$300,">0") + COUNTIFS($B$5:$B$300,B7,$A$5:$A$300,A7-1,$C$5:$C$300,"Game",$AG$5:$AG$300,">0"))>0,Reference!$B$119,IF((COUNTIFS($B$5:$B$300,B7,$A$5:$A$300,A7-2,$C$5:$C$300,"Bullpen",$AG$5:$AG$300,">0") + COUNTIFS($B$5:$B$300,B7,$A$5:$A$300,A7-2,$C$5:$C$300,"Game",$AG$5:$AG$300,">0"))>0,Reference!$B$120,1))) | AG7: =IF(AND(OR(I7="",O7="",P7=""),OR(R7="",W7=""),OR(X7="",AC7="")),"",IF(OR(I7="",O7="",P7=""),0,I7*O7*P7)+IF(OR(R7="",W7=""),0,R7*IFERROR(INDEX(Reference!$B$61:$B$62,MATCH("Bullpen",Reference!$A$61:$A$62,0)),0)*W7)+IF(OR(X7="",AC7=""),0,X7*(INDEX(Reference!$B$6:$B$11,MIN(5,MATCH(MAX(Reference!$A$6,MIN(Reference!$A$11,60)),Reference!$A$6:$A$11,1)))+(MAX(Reference!$A$6,MIN(Reference!$A$11,60))-INDEX(Reference!$A$6:$A$11,MIN(5,MATCH(MAX(Reference!$A$6,MIN(Reference!$A$11,60)),Reference!$A$6:$A$11,1))))*(INDEX(Reference!$B$6:$B$11,MIN(5,MATCH(MAX(Reference!$A$6,MIN(Reference!$A$11,60)),Reference!$A$6:$A$11,1))+1)-INDEX(Reference!$B$6:$B$11,MIN(5,MATCH(MAX(Reference!$A$6,MIN(Reference!$A$11,60)),Reference!$A$6:$A$11,1))))/(INDEX(Reference!$A$6:$A$11,MIN(5,MATCH(MAX(Reference!$A$6,MIN(Reference!$A$11,60)),Reference!$A$6:$A$11,1))+1)-INDEX(Reference!$A$6:$A$11,MIN(5,MATCH(MAX(Reference!$A$6,MIN(Reference!$A$11,60)),Reference!$A$6:$A$11,1)))))*AC7)) -> 95.2
A8: 46268 | B8: Adam Arther | C8: Moderate | D8: 120 | E8: 0.072916667 | F8: 0.086805556 | G8: =IF(OR(E8="",F8=""),"",(F8-E8)*1440) -> 20 | I8: =IF(H8<>"",H8,IF(G8="","",ROUND(G8*IFERROR(INDEX(Reference!$B$44:$B$50,MATCH(C8,Reference!$A$44:$A$50,0)),0),0))) -> 80 | J8: 75 | K8: 84 | L8: =IF(J8="","",IF(K8="",J8,AVERAGE(J8,K8))) -> 79.5 | M8: =IFERROR(INDEX(Roster!$D$5:$D$40,MATCH(B8,Roster!$A$5:$A$40,0)),"") -> 87.9 | N8: =IF(OR(L8="",M8="",M8=0),"",M8-L8) -> 8.4 | O8: =IF(OR(C8="Bullpen",C8="Game"),IFERROR(INDEX(Reference!$B$61:$B$62,MATCH(C8,Reference!$A$61:$A$62,0)),""),IF(D8="","",IF(AE8>1,((IF(1<=AE8,(AE8-1+3)*(INDEX(Reference!$B$6:$B$11,MIN(5,MATCH(MAX(Reference!$A$6,MIN(Reference!$A$11,MIN(D8,90))),Reference!$A$6:$A$11,1)))+(MAX(Reference!$A$6,MIN(Reference!$A$11,MIN(D8,90)))-INDEX(Reference!$A$6:$A$11,MIN(5,MATCH(MAX(Reference!$A$6,MIN(Reference!$A$11,MIN(D8,90))),Reference!$A$6:$A$11,1))))*(INDEX(Reference!$B$6:$B$11,MIN(5,MATCH(MAX(Reference!$A$6,MIN(Reference!$A$11,MIN(D8,90))),Reference!$A$6:$A$11,1))+1)-INDEX(Reference!$B$6:$B$11,MIN(5,MATCH(MAX(Reference!$A$6,MIN(Reference!$A$11,MIN(D8,90))),Reference!$A$6:$A$11,1))))/(INDEX(Reference!$A$6:$A$11,MIN(5,MATCH(MAX(Reference!$A$6,MIN(Reference!$A$11,MIN(D8,90))),Reference!$A$6:$A$11,1))+1)-INDEX(Reference!$A$6:$A$11,MIN(5,MATCH(MAX(Reference!$A$6,MIN(Reference!$A$11,MIN(D8,90))),Reference!$A$6:$A$11,1))))),0)+IF(2<=AE8,(AE8-2+3)*(INDEX(Reference!$B$6:$B$11,MIN(5,MATCH(MAX(Reference!$A$6,MIN(Reference!$A$11,MIN(D8,120))),Reference!$A$6:$A$11,1)))+(MAX(Reference!$A$6,MIN(Reference!$A$11,MIN(D8,120)))-INDEX(Reference!$A$6:$A$11,MIN(5,MATCH(MAX(Reference!$A$6,MIN(Reference!$A$11,MIN(D8,120))),Reference!$A$6:$A$11,1))))*(INDEX(Reference!$B$6:$B$11,MIN(5,MATCH(MAX(Reference!$A$6,MIN(Reference!$A$11,MIN(D8,120))),Reference!$A$6:$A$11,1))+1)-INDEX(Reference!$B$6:$B$11,MIN(5,MATCH(MAX(Reference!$A$6,MIN(Reference!$A$11,MIN(D8,120))),Reference!$A$6:$A$11,1))))/(INDEX(Reference!$A$6:$A$11,MIN(5,MATCH(MAX(Reference!$A$6,MIN(Reference!$A$11,MIN(D8,120))),Reference!$A$6:$A$11,1))+1)-INDEX(Reference!$A$6:$A$11,MIN(5,MATCH(MAX(Reference!$A$6,MIN(Reference!$A$11,MIN(D8,120))),Reference!$A$6:$A$11,1))))),0)+IF(3<=AE8,(AE8-3+3)*(INDEX(Reference!$B$6:$B$11,MIN(5,MATCH(MAX(Reference!$A$6,MIN(Reference!$A$11,MIN(D8,150))),Reference!$A$6:$A$11,1)))+(MAX(Reference!$A$6,MIN(Reference!$A$11,MIN(D8,150)))-INDEX(Reference!$A$6:$A$11,MIN(5,MATCH(MAX(Reference!$A$6,MIN(Reference!$A$11,MIN(D8,150))),Reference!$A$6:$A$11,1))))*(INDEX(Reference!$B$6:$B$11,MIN(5,MATCH(MAX(Reference!$A$6,MIN(Reference!$A$11,MIN(D8,150))),Reference!$A$6:$A$11,1))+1)-INDEX(Reference!$B$6:$B$11,MIN(5,MATCH(MAX(Reference!$A$6,MIN(Reference!$A$11,MIN(D8,150))),Reference!$A$6:$A$11,1))))/(INDEX(Reference!$A$6:$A$11,MIN(5,MATCH(MAX(Reference!$A$6,MIN(Reference!$A$11,MIN(D8,150))),Reference!$A$6:$A$11,1))+1)-INDEX(Reference!$A$6:$A$11,MIN(5,MATCH(MAX(Reference!$A$6,MIN(Reference!$A$11,MIN(D8,150))),Reference!$A$6:$A$11,1))))),0)+IF(4<=AE8,(AE8-4+3)*(INDEX(Reference!$B$6:$B$11,MIN(5,MATCH(MAX(Reference!$A$6,MIN(Reference!$A$11,MIN(D8,180))),Reference!$A$6:$A$11,1)))+(MAX(Reference!$A$6,MIN(Reference!$A$11,MIN(D8,180)))-INDEX(Reference!$A$6:$A$11,MIN(5,MATCH(MAX(Reference!$A$6,MIN(Reference!$A$11,MIN(D8,180))),Reference!$A$6:$A$11,1))))*(INDEX(Reference!$B$6:$B$11,MIN(5,MATCH(MAX(Reference!$A$6,MIN(Reference!$A$11,MIN(D8,180))),Reference!$A$6:$A$11,1))+1)-INDEX(Reference!$B$6:$B$11,MIN(5,MATCH(MAX(Reference!$A$6,MIN(Reference!$A$11,MIN(D8,180))),Reference!$A$6:$A$11,1))))/(INDEX(Reference!$A$6:$A$11,MIN(5,MATCH(MAX(Reference!$A$6,MIN(Reference!$A$11,MIN(D8,180))),Reference!$A$6:$A$11,1))+1)-INDEX(Reference!$A$6:$A$11,MIN(5,MATCH(MAX(Reference!$A$6,MIN(Reference!$A$11,MIN(D8,180))),Reference!$A$6:$A$11,1))))),0)+IF(5<=AE8,(AE8-5+3)*(INDEX(Reference!$B$6:$B$11,MIN(5,MATCH(MAX(Reference!$A$6,MIN(Reference!$A$11,MIN(D8,210))),Reference!$A$6:$A$11,1)))+(MAX(Reference!$A$6,MIN(Reference!$A$11,MIN(D8,210)))-INDEX(Reference!$A$6:$A$11,MIN(5,MATCH(MAX(Reference!$A$6,MIN(Reference!$A$11,MIN(D8,210))),Reference!$A$6:$A$11,1))))*(INDEX(Reference!$B$6:$B$11,MIN(5,MATCH(MAX(Reference!$A$6,MIN(Reference!$A$11,MIN(D8,210))),Reference!$A$6:$A$11,1))+1)-INDEX(Reference!$B$6:$B$11,MIN(5,MATCH(MAX(Reference!$A$6,MIN(Reference!$A$11,MIN(D8,210))),Reference!$A$6:$A$11,1))))/(INDEX(Reference!$A$6:$A$11,MIN(5,MATCH(MAX(Reference!$A$6,MIN(Reference!$A$11,MIN(D8,210))),Reference!$A$6:$A$11,1))+1)-INDEX(Reference!$A$6:$A$11,MIN(5,MATCH(MAX(Reference!$A$6,MIN(Reference!$A$11,MIN(D8,210))),Reference!$A$6:$A$11,1))))),0)+IF(6<=AE8,(AE8-6+3)*(INDEX(Reference!$B$6:$B$11,MIN(5,MATCH(MAX(Reference!$A$6,MIN(Reference!$A$11,MIN(D8,240))),Reference!$A$6:$A$11,1)))+(MAX(Reference!$A$6,MIN(Reference!$A$11,MIN(D8,240)))-INDEX(Reference!$A$6:$A$11,MIN(5,MATCH(MAX(Reference!$A$6,MIN(Reference!$A$11,MIN(D8,240))),Reference!$A$6:$A$11,1))))*(INDEX(Reference!$B$6:$B$11,MIN(5,MATCH(MAX(Reference!$A$6,MIN(Reference!$A$11,MIN(D8,240))),Reference!$A$6:$A$11,1))+1)-INDEX(Reference!$B$6:$B$11,MIN(5,MATCH(MAX(Reference!$A$6,MIN(Reference!$A$11,MIN(D8,240))),Reference!$A$6:$A$11,1))))/(INDEX(Reference!$A$6:$A$11,MIN(5,MATCH(MAX(Reference!$A$6,MIN(Reference!$A$11,MIN(D8,240))),Reference!$A$6:$A$11,1))+1)-INDEX(Reference!$A$6:$A$11,MIN(5,MATCH(MAX(Reference!$A$6,MIN(Reference!$A$11,MIN(D8,240))),Reference!$A$6:$A$11,1))))),0)+IF(7<=AE8,(AE8-7+3)*(INDEX(Reference!$B$6:$B$11,MIN(5,MATCH(MAX(Reference!$A$6,MIN(Reference!$A$11,MIN(D8,270))),Reference!$A$6:$A$11,1)))+(MAX(Reference!$A$6,MIN(Reference!$A$11,MIN(D8,270)))-INDEX(Reference!$A$6:$A$11,MIN(5,MATCH(MAX(Reference!$A$6,MIN(Reference!$A$11,MIN(D8,270))),Reference!$A$6:$A$11,1))))*(INDEX(Reference!$B$6:$B$11,MIN(5,MATCH(MAX(Reference!$A$6,MIN(Reference!$A$11,MIN(D8,270))),Reference!$A$6:$A$11,1))+1)-INDEX(Reference!$B$6:$B$11,MIN(5,MATCH(MAX(Reference!$A$6,MIN(Reference!$A$11,MIN(D8,270))),Reference!$A$6:$A$11,1))))/(INDEX(Reference!$A$6:$A$11,MIN(5,MATCH(MAX(Reference!$A$6,MIN(Reference!$A$11,MIN(D8,270))),Reference!$A$6:$A$11,1))+1)-INDEX(Reference!$A$6:$A$11,MIN(5,MATCH(MAX(Reference!$A$6,MIN(Reference!$A$11,MIN(D8,270))),Reference!$A$6:$A$11,1))))),0)+IF(8<=AE8,(AE8-8+3)*(INDEX(Reference!$B$6:$B$11,MIN(5,MATCH(MAX(Reference!$A$6,MIN(Reference!$A$11,MIN(D8,300))),Reference!$A$6:$A$11,1)))+(MAX(Reference!$A$6,MIN(Reference!$A$11,MIN(D8,300)))-INDEX(Reference!$A$6:$A$11,MIN(5,MATCH(MAX(Reference!$A$6,MIN(Reference!$A$11,MIN(D8,300))),Reference!$A$6:$A$11,1))))*(INDEX(Reference!$B$6:$B$11,MIN(5,MATCH(MAX(Reference!$A$6,MIN(Reference!$A$11,MIN(D8,300))),Reference!$A$6:$A$11,1))+1)-INDEX(Reference!$B$6:$B$11,MIN(5,MATCH(MAX(Reference!$A$6,MIN(Reference!$A$11,MIN(D8,300))),Reference!$A$6:$A$11,1))))/(INDEX(Reference!$A$6:$A$11,MIN(5,MATCH(MAX(Reference!$A$6,MIN(Reference!$A$11,MIN(D8,300))),Reference!$A$6:$A$11,1))+1)-INDEX(Reference!$A$6:$A$11,MIN(5,MATCH(MAX(Reference!$A$6,MIN(Reference!$A$11,MIN(D8,300))),Reference!$A$6:$A$11,1))))),0))/(AE8*(AE8+5)/2)),(INDEX(Reference!$B$6:$B$11,MIN(5,MATCH(MAX(Reference!$A$6,MIN(Reference!$A$11,D8)),Reference!$A$6:$A$11,1)))+(MAX(Reference!$A$6,MIN(Reference!$A$11,D8))-INDEX(Reference!$A$6:$A$11,MIN(5,MATCH(MAX(Reference!$A$6,MIN(Reference!$A$11,D8)),Reference!$A$6:$A$11,1))))*(INDEX(Reference!$B$6:$B$11,MIN(5,MATCH(MAX(Reference!$A$6,MIN(Reference!$A$11,D8)),Reference!$A$6:$A$11,1))+1)-INDEX(Reference!$B$6:$B$11,MIN(5,MATCH(MAX(Reference!$A$6,MIN(Reference!$A$11,D8)),Reference!$A$6:$A$11,1))))/(INDEX(Reference!$A$6:$A$11,MIN(5,MATCH(MAX(Reference!$A$6,MIN(Reference!$A$11,D8)),Reference!$A$6:$A$11,1))+1)-INDEX(Reference!$A$6:$A$11,MIN(5,MATCH(MAX(Reference!$A$6,MIN(Reference!$A$11,D8)),Reference!$A$6:$A$11,1)))))))) -> 1.7 | P8: =IF(N8="","",VLOOKUP(MAX(N8,0),Reference!$A$17:$B$20,2,TRUE())) -> 1 | Q8: =IF(AG8="","",AG8*IF(AF8="",1,AF8)) -> 136 | U8: =IF(S8="","",IF(T8="",S8,AVERAGE(S8,T8))) | V8: =IF(OR(U8="",M8="",M8=0),"",M8-U8) | W8: =IF(V8="","",VLOOKUP(MAX(V8,0),Reference!$A$17:$B$20,2,TRUE())) | AA8: =IF(Y8="","",IF(Z8="",Y8,AVERAGE(Y8,Z8))) | AB8: =IF(OR(AA8="",M8="",M8=0),"",M8-AA8) | AC8: =IF(AB8="","",VLOOKUP(MAX(AB8,0),Reference!$A$17:$B$20,2,TRUE())) | AD8: Rehab example: exact count, no time logged | AE8: =IF(AND(C8="Long Toss",N(D8)>90),1+ROUNDUP((D8-90)/30,0),1) -> 1 | AF8: =IF(OR(A8="",B8="",AND(C8<>"Bullpen",C8<>"Game")),"",IF((COUNTIFS($B$5:$B$300,B8,$A$5:$A$300,A8-1,$C$5:$C$300,"Bullpen",$AG$5:$AG$300,">0") + COUNTIFS($B$5:$B$300,B8,$A$5:$A$300,A8-1,$C$5:$C$300,"Game",$AG$5:$AG$300,">0"))>0,Reference!$B$119,IF((COUNTIFS($B$5:$B$300,B8,$A$5:$A$300,A8-2,$C$5:$C$300,"Bullpen",$AG$5:$AG$300,">0") + COUNTIFS($B$5:$B$300,B8,$A$5:$A$300,A8-2,$C$5:$C$300,"Game",$AG$5:$AG$300,">0"))>0,Reference!$B$120,1))) | AG8: =IF(AND(OR(I8="",O8="",P8=""),OR(R8="",W8=""),OR(X8="",AC8="")),"",IF(OR(I8="",O8="",P8=""),0,I8*O8*P8)+IF(OR(R8="",W8=""),0,R8*IFERROR(INDEX(Reference!$B$61:$B$62,MATCH("Bullpen",Reference!$A$61:$A$62,0)),0)*W8)+IF(OR(X8="",AC8=""),0,X8*(INDEX(Reference!$B$6:$B$11,MIN(5,MATCH(MAX(Reference!$A$6,MIN(Reference!$A$11,60)),Reference!$A$6:$A$11,1)))+(MAX(Reference!$A$6,MIN(Reference!$A$11,60))-INDEX(Reference!$A$6:$A$11,MIN(5,MATCH(MAX(Reference!$A$6,MIN(Reference!$A$11,60)),Reference!$A$6:$A$11,1))))*(INDEX(Reference!$B$6:$B$11,MIN(5,MATCH(MAX(Reference!$A$6,MIN(Reference!$A$11,60)),Reference!$A$6:$A$11,1))+1)-INDEX(Reference!$B$6:$B$11,MIN(5,MATCH(MAX(Reference!$A$6,MIN(Reference!$A$11,60)),Reference!$A$6:$A$11,1))))/(INDEX(Reference!$A$6:$A$11,MIN(5,MATCH(MAX(Reference!$A$6,MIN(Reference!$A$11,60)),Reference!$A$6:$A$11,1))+1)-INDEX(Reference!$A$6:$A$11,MIN(5,MATCH(MAX(Reference!$A$6,MIN(Reference!$A$11,60)),Reference!$A$6:$A$11,1)))))*AC8)) -> 136
